2018-03-15 11:42:38
Traceback (most recent call last):
  File "/Users/wbond/Library/Application Support/Sublime Text 3/Packages/SFTP/sftp/file_transfer.py", line 394, in handle_put_dirs
  File "/Users/wbond/Library/Application Support/Sublime Text 3/Packages/SFTP/sftp/sftp_transport.py", line 366, in cd
SFTP.sftp.errors.NotFoundError: Folder not found

During handling of the above exception, another exception occurred:

Traceback (most recent call last):
  File "/Users/wbond/Library/Application Support/Sublime Text 3/Packages/SFTP/sftp/threads.py", line 16, in run_with_except_hook
  File "/Users/wbond/Library/Application Support/Sublime Text 3/Packages/SFTP/sftp/threads.py", line 119, in handler
  File "/Users/wbond/Library/Application Support/Sublime Text 3/Packages/SFTP/sftp/commands.py", line 355, in run
  File "/Users/wbond/Library/Application Support/Sublime Text 3/Packages/SFTP/sftp/commands.py", line 510, in do_operation
  File "/Users/wbond/Library/Application Support/Sublime Text 3/Packages/SFTP/sftp/file_transfer.py", line 47, in handler
  File "/Users/wbond/Library/Application Support/Sublime Text 3/Packages/SFTP/sftp/sftp_transport.py", line 662, in put
  File "/Users/wbond/Library/Application Support/Sublime Text 3/Packages/SFTP/sftp/file_transfer.py", line 397, in handle_put_dirs
  File "/Users/wbond/Library/Application Support/Sublime Text 3/Packages/SFTP/sftp/sftp_transport.py", line 366, in cd
SFTP.sftp.errors.NotFoundError: Folder not found
2018-03-15 11:45:08
Traceback (most recent call last):
  File "/Users/wbond/Library/Application Support/Sublime Text 3/Packages/SFTP/sftp/file_transfer.py", line 394, in handle_put_dirs
  File "/Users/wbond/Library/Application Support/Sublime Text 3/Packages/SFTP/sftp/sftp_transport.py", line 366, in cd
SFTP.sftp.errors.NotFoundError: Folder not found

During handling of the above exception, another exception occurred:

Traceback (most recent call last):
  File "/Users/wbond/Library/Application Support/Sublime Text 3/Packages/SFTP/sftp/threads.py", line 16, in run_with_except_hook
  File "/Users/wbond/Library/Application Support/Sublime Text 3/Packages/SFTP/sftp/threads.py", line 119, in handler
  File "/Users/wbond/Library/Application Support/Sublime Text 3/Packages/SFTP/sftp/commands.py", line 355, in run
  File "/Users/wbond/Library/Application Support/Sublime Text 3/Packages/SFTP/sftp/commands.py", line 510, in do_operation
  File "/Users/wbond/Library/Application Support/Sublime Text 3/Packages/SFTP/sftp/file_transfer.py", line 47, in handler
  File "/Users/wbond/Library/Application Support/Sublime Text 3/Packages/SFTP/sftp/sftp_transport.py", line 662, in put
  File "/Users/wbond/Library/Application Support/Sublime Text 3/Packages/SFTP/sftp/file_transfer.py", line 397, in handle_put_dirs
  File "/Users/wbond/Library/Application Support/Sublime Text 3/Packages/SFTP/sftp/sftp_transport.py", line 366, in cd
SFTP.sftp.errors.NotFoundError: Folder not found
2018-03-15 11:47:38
Traceback (most recent call last):
  File "/Users/wbond/Library/Application Support/Sublime Text 3/Packages/SFTP/sftp/file_transfer.py", line 394, in handle_put_dirs
  File "/Users/wbond/Library/Application Support/Sublime Text 3/Packages/SFTP/sftp/sftp_transport.py", line 366, in cd
SFTP.sftp.errors.NotFoundError: Folder not found

During handling of the above exception, another exception occurred:

Traceback (most recent call last):
  File "/Users/wbond/Library/Application Support/Sublime Text 3/Packages/SFTP/sftp/threads.py", line 16, in run_with_except_hook
  File "/Users/wbond/Library/Application Support/Sublime Text 3/Packages/SFTP/sftp/threads.py", line 119, in handler
  File "/Users/wbond/Library/Application Support/Sublime Text 3/Packages/SFTP/sftp/commands.py", line 355, in run
  File "/Users/wbond/Library/Application Support/Sublime Text 3/Packages/SFTP/sftp/commands.py", line 510, in do_operation
  File "/Users/wbond/Library/Application Support/Sublime Text 3/Packages/SFTP/sftp/file_transfer.py", line 47, in handler
  File "/Users/wbond/Library/Application Support/Sublime Text 3/Packages/SFTP/sftp/sftp_transport.py", line 662, in put
  File "/Users/wbond/Library/Application Support/Sublime Text 3/Packages/SFTP/sftp/file_transfer.py", line 397, in handle_put_dirs
  File "/Users/wbond/Library/Application Support/Sublime Text 3/Packages/SFTP/sftp/sftp_transport.py", line 366, in cd
SFTP.sftp.errors.NotFoundError: Folder not found
2018-03-15 12:31:43
Traceback (most recent call last):
  File "/Users/wbond/Library/Application Support/Sublime Text 3/Packages/SFTP/sftp/sftp_transport.py", line 558, in mkdir
  File "/Users/wbond/Library/Application Support/Sublime Text 3/Packages/SFTP/sftp/sftp_transport.py", line 366, in cd
SFTP.sftp.errors.NotFoundError: Folder not found

During handling of the above exception, another exception occurred:

Traceback (most recent call last):
  File "/Users/wbond/Library/Application Support/Sublime Text 3/Packages/SFTP/sftp/threads.py", line 16, in run_with_except_hook
  File "/Users/wbond/Library/Application Support/Sublime Text 3/Packages/SFTP/sftp/threads.py", line 119, in handler
  File "/Users/wbond/Library/Application Support/Sublime Text 3/Packages/SFTP/sftp/commands.py", line 355, in run
  File "/Users/wbond/Library/Application Support/Sublime Text 3/Packages/SFTP/sftp/commands.py", line 510, in do_operation
  File "/Users/wbond/Library/Application Support/Sublime Text 3/Packages/SFTP/sftp/file_transfer.py", line 47, in handler
  File "/Users/wbond/Library/Application Support/Sublime Text 3/Packages/SFTP/sftp/sftp_transport.py", line 662, in put
  File "/Users/wbond/Library/Application Support/Sublime Text 3/Packages/SFTP/sftp/file_transfer.py", line 379, in handle_put_dirs
  File "/Users/wbond/Library/Application Support/Sublime Text 3/Packages/SFTP/sftp/file_transfer.py", line 47, in handler
  File "/Users/wbond/Library/Application Support/Sublime Text 3/Packages/SFTP/sftp/sftp_transport.py", line 561, in mkdir
  File "/Users/wbond/Library/Application Support/Sublime Text 3/Packages/SFTP/sftp/sftp_transport.py", line 366, in cd
SFTP.sftp.errors.NotFoundError: Folder not found
